Workbook

Sheet Performance Summary
B2: THOTA HOSPITALITY LLP
B3: Performance Summary
B4: P A R T I C U L A R S | C4: FY2025-26 (Actuals) | F4: FY2025-26 (Projection) | G4: Totals (FY2025-26)
C5: QTR 1 - 25 | D5: QTR 2 - 25 | E5: QTR 3 - 25 | F5: QTR 4 - 25
B6: Hospitality Services | C6: =sum('P&L Detailed'!B5:D7) -> 2696923 | D6: =sum('P&L Detailed'!E5:G7) -> 2645548 | E6: =sum('P&L Detailed'!H5:J7) -> 3735301 | F6: =sum('P&L Detailed'!K5:M7) -> 3734691.9 | G6: =C6+D6+E6+F6 -> 12812464
B7: Studio Services | C7: =sum('P&L Detailed'!B8:D8) -> 40950 | D7: =sum('P&L Detailed'!E8:G8) -> 57000 | E7: =sum('P&L Detailed'!H8:J8) -> 78200 | F7: =sum('P&L Detailed'!K8:M8) -> 101745 | G7: =C7+D7+E7+F7 -> 277895
B8: Other Income
B9: Credit Note
B10: SALES | C10: =SUM(C6:C9) -> 2737873 | D10: =SUM(D6:D9) -> 2702548 | E10: =SUM(E6:E9) -> 3813501 | F10: =SUM(F6:F9) -> 3836436.9 | G10: =SUM(G6:G9) -> 13090359 | I10: Target
B12: COGS | C12: ='P&L Detailed'!B10+'P&L Detailed'!C10+'P&L Detailed'!D10 -> 624743 | D12: ='P&L Detailed'!E10+'P&L Detailed'!F10+'P&L Detailed'!G10 -> 553878 | E12: ='P&L Detailed'!H10+'P&L Detailed'!I10+'P&L Detailed'!J10 -> 788177 | F12: ='P&L Detailed'!K10+'P&L Detailed'!L10+'P&L Detailed'!M10 -> 1089006.7 | G12: =C12+D12+E12+F12 -> 3055804.7
B13: Direct Expenses | C13: ='P&L Detailed'!B15+'P&L Detailed'!C15+'P&L Detailed'!D15 -> 99160 | D13: ='P&L Detailed'!E15+'P&L Detailed'!F15+'P&L Detailed'!G15 -> 88568 | E13: ='P&L Detailed'!H15+'P&L Detailed'!I15+'P&L Detailed'!J15 -> 72944 | F13: ='P&L Detailed'!K15+'P&L Detailed'!L15+'P&L Detailed'!M15 -> 135711.87 | G13: =C13+D13+E13+F13 -> 396383.87
B15: Gross Profit | C15: =C10-C12-C13 -> 2013970 | D15: =D10-D12-D13 -> 2060102 | E15: =E10-E12-E13 -> 2952380 | F15: =F10-F12-F13 -> 2611718.3 | G15: =G10-G12-G13 -> 9638170.3
B16: Gross Profit % | C16: =C15/C10 -> 0.73559657 | D16: =D15/D10 -> 0.76228137 | E16: =E15/E10 -> 0.77419148 | F16: =F15/F10 -> 0.68076667 | G16: =G15/G10 -> 0.73628007
B18: Indirect Income | C18: ='P&L Detailed'!B25+'P&L Detailed'!C25+'P&L Detailed'!D25 -> 0 | D18: ='P&L Detailed'!E25+'P&L Detailed'!F25+'P&L Detailed'!G25 -> 0 | E18: ='P&L Detailed'!F25+'P&L Detailed'!G25+'P&L Detailed'!H25 -> 0 | F18: ='P&L Detailed'!G25+'P&L Detailed'!H25+'P&L Detailed'!I25 -> 0 | G18: =C18+D18+E18+F18 -> 0
B19: Indirect Expenses | C19: ='P&L Detailed'!B30+'P&L Detailed'!C30+'P&L Detailed'!D30 -> 1109301 | D19: ='P&L Detailed'!E30+'P&L Detailed'!F30+'P&L Detailed'!G30 -> 1111251.1 | E19: ='P&L Detailed'!H30+'P&L Detailed'!I30+'P&L Detailed'!J30 -> 1291284.1 | F19: ='P&L Detailed'!K30+'P&L Detailed'!L30+'P&L Detailed'!M30 -> 1468498.1 | G19: =C19+D19+E19+F19 -> 4980334.2
B21: EBITDA | C21: =C15+C18-C19 -> 904669 | D21: =D15+D18-D19 -> 948850.89 | E21: =E15+E18-E19 -> 1661095.9 | F21: =F15+F18-F19 -> 1143220.3 | G21: =G15+G18-G19 -> 4657836.1
B22: EBITDA % | C22: =C21/C10 -> 0.33042767 | D22: =D21/D10 -> 0.35109493 | E22: =E21/E10 -> 0.43558292 | F22: =F21/F10 -> 0.29799012 | G22: =G21/G10 -> 0.35582188
B24: Finance Cost | C24: ='P&L Detailed'!B42+'P&L Detailed'!C42+'P&L Detailed'!D42 -> 1466.5 | D24: ='P&L Detailed'!E42+'P&L Detailed'!F42+'P&L Detailed'!G42 -> 3096.6 | E24: ='P&L Detailed'!H42+'P&L Detailed'!I42+'P&L Detailed'!J42 -> 2304.3 | F24: ='P&L Detailed'!K42+'P&L Detailed'!L42+'P&L Detailed'!M42 -> 2621.52 | G24: =C24+D24+E24+F24 -> 9488.92
B25: Depreciation | C25: ='P&L Detailed'!B47+'P&L Detailed'!C47+'P&L Detailed'!D47 -> 70000 | D25: ='P&L Detailed'!E47+'P&L Detailed'!F47+'P&L Detailed'!G47 -> 70000 | E25: ='P&L Detailed'!H47+'P&L Detailed'!I47+'P&L Detailed'!J47 -> 70000 | F25: ='P&L Detailed'!K47+'P&L Detailed'!L47+'P&L Detailed'!M47 -> 70000 | G25: =C25+D25+E25+F25 -> 280000
B26: Income Tax | C26: - | D26: - | E26: - | F26: -
B28: PAT | C28: =C21-(C24+C25) -> 833202.5 | D28: =D21-(D24+D25) -> 875754.29 | E28: =E21-(E24+E25) -> 1588791.6 | F28: =F21-(F24+F25) -> 1070598.8 | G28: =G21-(G24+G25) -> 4368347.2
B29: PAT % | C29: =C28/C10 -> 0.30432474 | D29: =D28/D10 -> 0.32404764 | E29: =E28/E10 -> 0.41662284 | F29: =F28/F10 -> 0.2790607 | G29: =G28/G10 -> 0.33370721

Sheet Segment_wise_Revenue
A1: REVENUE / SALES
A2: Month | B2: Morning Glory | C2: Al Fresco | D2: Sunset Soiree | E2: Studio | F2: Other Income | G2: Total | H2: Percentage
A3: April | B3: 118348 | C3: 264870 | D3: 524656 | G3: =SUM(Segment_wise_Revenue!$B3:$F3) -> 907874 | H3: =Segment_wise_Revenue!$G3/$G$15 -> 0.07027057
A4: May | B4: 181875 | C4: 344792 | D4: 525237 | E4: 27450 | G4: =SUM(Segment_wise_Revenue!$B4:$F4) -> 1079354 | H4: =Segment_wise_Revenue!$G4/$G$15 -> 0.083543334
A5: June | B5: 63993 | C5: 323481 | D5: 349671 | E5: 13500 | G5: =SUM(Segment_wise_Revenue!$B5:$F5) -> 750645 | H5: =Segment_wise_Revenue!$G5/$G$15 -> 0.058100851
A6: July | B6: 113740 | C6: 340593 | D6: 493341 | E6: 20500 | G6: =SUM(Segment_wise_Revenue!$B6:$F6) -> 968174 | H6: =Segment_wise_Revenue!$G6/$G$15 -> 0.074937864
A7: August | B7: 222121 | C7: 370930 | D7: 261784 | E7: 23500 | G7: =SUM(Segment_wise_Revenue!$B7:$F7) -> 878335 | H7: =Segment_wise_Revenue!$G7/$G$15 -> 0.067984215
A8: September | B8: 49180 | C8: 436280 | D8: 357579 | E8: 13000 | G8: =SUM(Segment_wise_Revenue!$B8:$F8) -> 856039 | H8: =Segment_wise_Revenue!$G8/$G$15 -> 0.066258477
A9: October | B9: 100602 | C9: 754392 | D9: 363649 | E9: 20900 | G9: =SUM(Segment_wise_Revenue!$B9:$F9) -> 1239543 | H9: =Segment_wise_Revenue!$G9/$G$15 -> 0.09594216
A10: November | B10: 159971 | C10: =586885+9851 -> 596736 | D10: 426519 | E10: 19500 | G10: =SUM(Segment_wise_Revenue!$B10:$F10) -> 1202726 | H10: =Segment_wise_Revenue!$G10/$G$15 -> 0.093092479
A11: December | B11: =108129-37800 -> 70329 | C11: 582752 | D11: 680351 | E11: 37800 | G11: =SUM(Segment_wise_Revenue!$B11:$F11) -> 1371232 | H11: =Segment_wise_Revenue!$G11/$G$15 -> 0.10613505
A12: January | B12: 90700 | C12: 385146 | D12: 460167 | E12: 25500 | G12: =SUM(Segment_wise_Revenue!$B12:$F12) -> 961513 | H12: =Segment_wise_Revenue!$G12/$G$15 -> 0.074422295
A13: February | B13: =B12+(B12*25%) -> 113375 | C13: =C12+(C12*25%) -> 481432.5 | D13: =D12+(D12*25%) -> 575208.75 | E13: =E12+(E12*25%) -> 31875 | G13: =SUM(Segment_wise_Revenue!$B13:$F13) -> 1201891.2 | H13: =Segment_wise_Revenue!$G13/$G$15 -> 0.093027868
A14: March | B14: =B13+(B13*25%) -> 141718.75 | C14: =C13+(C13*25%) -> 601790.62 | D14: =D13+(D13*25%) -> 719010.94 | E14: =E13+(E13*25%) -> 39843.75 | F14: =F13+(F13*25%) -> 0 | G14: =SUM(Segment_wise_Revenue!$B14:$F14) -> 1502364.1 | H14: =Segment_wise_Revenue!$G14/$G$15 -> 0.11628484
A15: Totals | B15: =SUM(B3:B14) -> 1425952.8 | C15: =SUM(C3:C14) -> 5483195.1 | D15: =SUM(D3:D14) -> 5737173.7 | E15: =SUM(E3:E14) -> 273368.75 | F15: =SUM(F3:F14) -> 0 | G15: =SUM(G3:G14) -> 12919690 | H15: =SUBTOTAL(109,H3:H14) -> 1
B16: =B15/G15 -> 0.11037051 | C16: =C15/G15 -> 0.42440608 | D16: =D15/G15 -> 0.44406433 | E16: =E15/G15 -> 0.021159079 | G16: 1
G17: =ROUND(SUM(G3:G14),0) -> 12919690

Sheet P&L Detailed
A1: THOTA HOSPITALITY LLP
A2: Profit & Loss A/c
A3: Particulars | B3: APR-25 | C3: MAY-25 | D3: JUN-25 | E3: JUL-25 | F3: AUG-25 | G3: SEPT-25 | H3: OCT-25 | I3: NOV-25 | J3: DEC-25 | K3: JAN-26 | L3: FEB-26 (Proj) | M3: MAR-26 (Proj) | N3: Totals
A4: Revenue from operations | B4: =SUM(B5:B9) -> 907874 | C4: =SUM(C5:C9) -> 1079354 | D4: =SUM(D5:D9) -> 750645 | E4: =SUM(E5:E9) -> 968174 | F4: =SUM(F5:F9) -> 878335 | G4: =SUM(G5:G9) -> 856039 | H4: =SUM(H5:H9) -> 1239543 | I4: =SUM(I5:I9) -> 1202726 | ... M4: =SUM(M5:M9) -> 1624957 | N4: =SUM(B4:M4) -> 13090359
A5: =Segment_wise_Revenue!B2 -> Morning Glory | B5: =Segment_wise_Revenue!$B$3 -> 118348 | C5: =Segment_wise_Revenue!B4 -> 181875 | D5: =Segment_wise_Revenue!B5 -> 63993 | E5: =Segment_wise_Revenue!B6 -> 113740 | F5: =Segment_wise_Revenue!B7 -> 222121 | G5: =Segment_wise_Revenue!B8 -> 49180 | H5: =Segment_wise_Revenue!B9 -> 100602 | I5: =Segment_wise_Revenue!B10 -> 159971 | J5: =Segment_wise_Revenue!B11 -> 70329 | K5: =Segment_wise_Revenue!B12 -> 90700 | L5: =K5*1.3 -> 117910 | M5: =L5*1.3 -> 153283 | N5: =SUM(B5:M5) -> 1442052
A6: =Segment_wise_Revenue!C2 -> Al Fresco | B6: =Segment_wise_Revenue!$C$3 -> 264870 | C6: =Segment_wise_Revenue!C4 -> 344792 | D6: =Segment_wise_Revenue!C5 -> 323481 | E6: =Segment_wise_Revenue!C6 -> 340593 | F6: =Segment_wise_Revenue!C7 -> 370930 | G6: =Segment_wise_Revenue!C8 -> 436280 | H6: =Segment_wise_Revenue!C9 -> 754392 | I6: =Segment_wise_Revenue!C10 -> 596736 | J6: =Segment_wise_Revenue!C11 -> 582752 | K6: =Segment_wise_Revenue!C12 -> 385146 | L6: =K6*1.3 -> 500689.8 | M6: =L6*1.3 -> 650896.74 | N6: =SUM(B6:M6) -> 5551558.5
A7: =Segment_wise_Revenue!D2 -> Sunset Soiree | B7: =Segment_wise_Revenue!$D$3 -> 524656 | C7: =Segment_wise_Revenue!D4 -> 525237 | D7: =Segment_wise_Revenue!D5 -> 349671 | E7: =Segment_wise_Revenue!D6 -> 493341 | F7: =Segment_wise_Revenue!D7 -> 261784 | G7: =Segment_wise_Revenue!D8 -> 357579 | H7: =Segment_wise_Revenue!D9 -> 363649 | I7: =Segment_wise_Revenue!D10 -> 426519 | J7: =Segment_wise_Revenue!D11 -> 680351 | K7: =Segment_wise_Revenue!D12 -> 460167 | L7: =K7*1.3 -> 598217.1 | M7: =L7*1.3 -> 777682.23 | N7: =SUM(B7:M7) -> 5818853.3
A8: =Segment_wise_Revenue!E2 -> Studio | B8: =Segment_wise_Revenue!$E$3 | C8: =Segment_wise_Revenue!E4 -> 27450 | D8: =Segment_wise_Revenue!E5 -> 13500 | E8: =Segment_wise_Revenue!E6 -> 20500 | F8: =Segment_wise_Revenue!E7 -> 23500 | G8: =Segment_wise_Revenue!E8 -> 13000 | H8: =Segment_wise_Revenue!E9 -> 20900 | I8: =Segment_wise_Revenue!E10 -> 19500 | J8: =Segment_wise_Revenue!E11 -> 37800 | K8: =Segment_wise_Revenue!E12 -> 25500 | L8: =K8*1.3 -> 33150 | M8: =L8*1.3 -> 43095 | N8: =SUM(B8:M8) -> 277895
A9: Other Income | B9: =Segment_wise_Revenue!$F$3 | N9: =SUM(B9:M9) -> 0
A10: Purchase Cost | B10: =sum(B11:B13) -> 203541 | C10: =sum(C11:C13) -> 211829 | D10: =sum(D11:D13) -> 209373 | E10: =sum(E11:E13) -> 177557 | F10: =sum(F11:F13) -> 172324 | G10: =sum(G11:G13) -> 203997 | H10: =sum(H11:H13) -> 233183 | I10: =sum(I11:I13) -> 234574 | ... M10: =sum(M11:M13) -> 461258.46 | N10: =SUM(B10:M10) -> 3055804.7
A11: Thota Kitchen | B11: 154165 | C11: 152583 | D11: 147063 | E11: 125852 | F11: 134779 | G11: 108655 | H11: 112015 | I11: 141303 | J11: 185774 | K11: 167420 | L11: =K11*1.3 -> 217646 | M11: =L11*1.3 -> 282939.8
A12: Thota Decor | B12: 47967 | C12: 49886 | D12: 59410 | E12: 51705 | F12: 37545 | G12: 90712 | H12: 119715 | I12: 69721 | J12: 100606 | K12: 95116 | L12: =K12*1.3 -> 123650.8 | M12: =L12*1.3 -> 160746.04
A13: Studio Decor | B13: 1409 | C13: 9360 | D13: 2900 | G13: 4630 | H13: 1453 | I13: 23550 | J13: 34040 | K13: 10398 | L13: =K13*1.3 -> 13517.4 | M13: =L13*1.3 -> 17572.62
A15: Direct Expenses | B15: =sum(B16:B17) -> 35008 | C15: =sum(C16:C17) -> 34233 | D15: =sum(D16:D17) -> 29919 | E15: =sum(E16:E17) -> 30792 | F15: =sum(F16:F17) -> 29948 | G15: =sum(G16:G17) -> 27828 | H15: =sum(H16:H17) -> 19090 | I15: =sum(I16:I17) -> 21450 | ... M15: =sum(M16:M17) -> 57481.97 | N15: =SUM(B15:M15) -> 396383.87
A16: Fuel Expenses | B16: 25851 | C16: 30795 | D16: 24505 | E16: 16224 | F16: 29662 | G16: 23760 | H16: 18050 | I16: 17915 | J16: 31400 | K16: 31290 | L16: =K16*1.3 -> 40677 | M16: =L16*1.3 -> 52880.1
A17: Transportation Expense | B17: 9157 | C17: 3438 | D17: 5414 | E17: 14568 | F17: 286 | G17: 4068 | H17: 1040 | I17: 3535 | J17: 1004 | K17: 2723 | L17: =K17*1.3 -> 3539.9 | M17: =L17*1.3 -> 4601.87
A20: COGS-Total | B20: =B10+B15 -> 238549 | C20: =C10+C15 -> 246062 | D20: =D10+D15 -> 239292 | E20: =E10+E15 -> 208349 | F20: =F10+F15 -> 202272 | G20: =G10+G15 -> 231825 | H20: =H10+H15 -> 252273 | I20: =I10+I15 -> 256024 | ... M20: =M10+M15 -> 518740.43 | N20: =SUM(B20:M20) -> 3452188.5
A22: Gross Profit | B22: =B4-B20 -> 669325 | C22: =C4-C20 -> 833292 | D22: =D4-D20 -> 511353 | E22: =E4-E20 -> 759825 | F22: =F4-F20 -> 676063 | G22: =G4-G20 -> 624214 | H22: =H4-H20 -> 987270 | I22: =I4-I20 -> 946702 | ... N22: =N4-N20 -> 9638170.3
A23: Gross Profit % | B23: =B22/B4 -> 0.73724438 | C23: =C22/C4 -> 0.77202845 | D23: =D22/D4 -> 0.68121815 | E23: =E22/E4 -> 0.78480211 | F23: =F22/F4 -> 0.76970973 | G23: =G22/G4 -> 0.72918874 | H23: =H22/H4 -> 0.79647902 | I23: =I22/I4 -> 0.78713024 | ... N23: =N22/N4 -> 0.73628007
A25: Indirect Income | B25: =sum(B26:B29) -> 0 | C25: =sum(C26:C29) -> 0 | D25: =sum(D26:D29) -> 0 | E25: =sum(E26:E29) -> 0 | F25: =sum(F26:F29) -> 0 | G25: =sum(G26:G29) -> 0 | H25: =sum(H26:H29) -> 0 | I25: =sum(I26:I29) -> 0 | ... M25: =sum(M26:M29) -> 0 | N25: =SUM(B25:M25) -> 0
A26: Buyback
A27: Discount Recieved
A28: Interest Income
A29: Other Income
A30: Indirect Expenses | B30: =SUM(B31:B38) -> 336727 | C30: =SUM(C31:C38) -> 391689 | D30: =SUM(D31:D38) -> 380885 | E30: =SUM(E31:E38) -> 358748 | F30: =SUM(F31:F38) -> 361359 | G30: =SUM(G31:G38) -> 391144.11 | H30: =SUM(H31:H38) -> 440552.78 | I30: =SUM(I31:I38) -> 416045.31 | ... M30: =SUM(M31:M38) -> 536822.55 | N30: =SUM(B30:M30) -> 4980334.2
A31: Advertisement/Marketing | B31: =Schedule_OPEX!B22 -> 8054 | C31: =Schedule_OPEX!C22 -> 14232 | D31: =Schedule_OPEX!D22 -> 5015 | E31: =Schedule_OPEX!E22 -> 11016 | F31: =Schedule_OPEX!F22 -> 5000 | G31: =Schedule_OPEX!G22 -> 5000 | H31: =Schedule_OPEX!H22 -> 8070 | I31: =Schedule_OPEX!I22 -> 0 | ... M31: =Schedule_OPEX!M22 -> 4840
A32: Office & Administrative Overheads | B32: =Schedule_OPEX!B3 -> 13104 | C32: =Schedule_OPEX!C3 -> 43643 | D32: =Schedule_OPEX!D3 -> 91673 | E32: =Schedule_OPEX!E3 -> 33801 | F32: =Schedule_OPEX!F3 -> 26363 | G32: =Schedule_OPEX!G3 -> 33402 | H32: =Schedule_OPEX!H3 -> 75548.72 | I32: =Schedule_OPEX!I3 -> 44779 | ... M32: =Schedule_OPEX!M3 -> 152643.92
A33: Payroll Expenses | B33: =Schedule_OPEX!B15 -> 315569 | C33: =Schedule_OPEX!C15 -> 333814 | D33: =Schedule_OPEX!D15 -> 284197 | E33: =Schedule_OPEX!E15 -> 313931 | F33: =Schedule_OPEX!F15 -> 329926 | G33: =Schedule_OPEX!G15 -> 353303 | H33: =Schedule_OPEX!H15 -> 356918 | I33: =Schedule_OPEX!I15 -> 371259 | ... M33: =Schedule_OPEX!M15 -> 379338.63
A34: Rates & Taxes | B34: =Schedule_OPEX!B26 | C34: =Schedule_OPEX!C26 | D34: =Schedule_OPEX!D26 | E34: =Schedule_OPEX!E26 | F34: =Schedule_OPEX!F26 -> 70 | G34: =Schedule_OPEX!G26 -> -560.89 | H34: =Schedule_OPEX!H26 -> 16.06 | I34: =Schedule_OPEX!I26 -> 7.31 | ... M34: =Schedule_OPEX!M26
A35: Travelling Expense
A36: Freight Outward
A37: Professional Service Charges
A38: Write Off / (-)Write Back
A39: EBITDA | B39: =B22+B25-B30 -> 332598 | C39: =C22+C25-C30 -> 441603 | D39: =D22+D25-D30 -> 130468 | E39: =E22+E25-E30 -> 401077 | F39: =F22+F25-F30 -> 314704 | G39: =G22+G25-G30 -> 233069.89 | H39: =H22+H25-H30 -> 546717.22 | I39: =I22+I25-I30 -> 530656.69 | ... N39: =N22+N25-N30 -> 4657836.1
A40: EBITDA % | B40: =B39/B4 -> 0.36634819 | C40: =C39/C4 -> 0.40913639 | D40: =D39/D4 -> 0.17380786 | E40: =E39/E4 -> 0.41426128 | F40: =F39/F4 -> 0.35829609 | G40: =G39/G4 -> 0.2722655 | H40: =H39/H4 -> 0.44106354 | I40: =I39/I4 -> 0.44121162 | ... N40: =N39/N4 -> 0.35582188
A42: Finance Cost | B42: =Schedule_OPEX!B11 -> 561.6 | C42: =Schedule_OPEX!C11 -> 449.5 | D42: =Schedule_OPEX!D11 -> 455.4 | E42: =Schedule_OPEX!E11 -> 597 | F42: =Schedule_OPEX!F11 -> 1719.7 | G42: =Schedule_OPEX!G11 -> 779.9 | H42: =Schedule_OPEX!H11 -> 691.4 | I42: =Schedule_OPEX!I11 -> 791.7 | ... M42: =Schedule_OPEX!M11 -> 958.32 | N42: =SUM(B42:M42) -> 9488.92
A44: PBT | B44: =B39-B42 -> 332036.4 | C44: =C39-C42 -> 441153.5 | D44: =D39-D42 -> 130012.6 | E44: =E39-E42 -> 400480 | F44: =F39-F42 -> 312984.3 | G44: =G39-G42 -> 232289.99 | H44: =H39-H42 -> 546025.82 | I44: =I39-I42 -> 529864.99 | ... N44: =N39-N42 -> 4648347.2
A45: PBT % | B45: =B44/B4 -> 0.36572961 | C45: =C44/C4 -> 0.40871994 | D45: =D44/D4 -> 0.17320118 | E45: =E44/E4 -> 0.41364465 | F45: =F44/F4 -> 0.35633819 | G45: =G44/G4 -> 0.27135445 | H45: =H44/H4 -> 0.44050575 | I45: =I44/I4 -> 0.44055337 | ... N45: =N44/N4 -> 0.355097
A47: Depreciation | B47: =280000/12 -> 23333.333 | C47: =280000/12 -> 23333.333 | D47: =280000/12 -> 23333.333 | E47: =280000/12 -> 23333.333 | F47: =280000/12 -> 23333.333 | G47: =280000/12 -> 23333.333 | H47: =280000/12 -> 23333.333 | I47: =280000/12 -> 23333.333 | ... M47: =280000/12 -> 23333.333 | N47: =SUM(B47:M47) -> 280000
A49: PAT | B49: =B44-B47 -> 308703.07 | C49: =C44-C47 -> 417820.17 | D49: =D44-D47 -> 106679.27 | E49: =E44-E47 -> 377146.67 | F49: =F44-F47 -> 289650.97 | G49: =G44-G47 -> 208956.66 | H49: =H44-H47 -> 522692.49 | I49: =I44-I47 -> 506531.66 | ... N49: =N44-N47 -> 4368347.2
...

Sheet Schedule_OPEX
A1: Indirect Expenses | B1: Apr-Mar 25-26 | N1: Total
A2: Particulars | B2: APR | C2: MAY | D2: JUN | E2: JUL | F2: AUG | G2: SEPT | H2: OCT | I2: NOV | J2: DEC | K2: JAN | L2: FEB | M2: MAR
A3: Office & Administrative Overheads | B3: =SUM(B4:B10) -> 13104 | C3: =SUM(C4:C10) -> 43643 | D3: =SUM(D4:D10) -> 91673 | E3: =SUM(E4:E10) -> 33801 | F3: =SUM(F4:F10) -> 26363 | G3: =SUM(G4:G10) -> 33402 | H3: =SUM(H4:H10) -> 75548.72 | I3: =SUM(I4:I10) -> 44779 | ... M3: =SUM(M4:M10) -> 152643.92 | N3: =SUM(B3:M3) -> 825231.84
A4: Local Conveyance | B4: 1210 | H4: 530 | L4: =K4*1.1 -> 0 | M4: =L4*1.1 -> 0
A5: Office Expenses | B5: 300 | C5: 14097 | D5: 11018 | E5: 3180 | F5: 5868 | G5: 3017 | H5: 17264 | I5: 2296 | J5: 8719 | K5: 2807 | L5: =K5*1.1 -> 3087.7 | M5: =L5*1.1 -> 3396.47
A6: Printing & Stationery | D6: 1316 | E6: 531 | H6: 1133 | L6: =K6*1.1 -> 0 | M6: =L6*1.1 -> 0
A7: Registration & Subscription | B7: 1046 | C7: 1377 | D7: 1559 | E7: 1487 | F7: 1487 | G7: 1369 | H7: 2856 | J7: 2738 | K7: 9500 | L7: =K7*1.1 -> 10450 | M7: =L7*1.1 -> 11495
A8: Staff Welfare | B8: 9784 | C8: 24799 | D8: 75338 | E8: 28202 | F8: 18028 | G8: 27386 | H8: 52965 | I8: 38542 | J8: 32250 | K8: 111921 | L8: =K8*1.1 -> 123113.1 | M8: =L8*1.1 -> 135424.41
A9: Telephone & Internet Charges | B9: 764 | C9: 3370 | D9: 2442 | E9: 401 | F9: 980 | G9: 1630 | H9: 800.72 | I9: 3941 | J9: 1648 | K9: 1924 | L9: =K9*1.1 -> 2116.4 | M9: =L9*1.1 -> 2328.04
L10: =K10*1.1 -> 0 | M10: =L10*1.1 -> 0
A11: Finance Cost | B11: =SUM(B12:B14) -> 561.6 | C11: =SUM(C12:C14) -> 449.5 | D11: =SUM(D12:D14) -> 455.4 | E11: =SUM(E12:E14) -> 597 | F11: =SUM(F12:F14) -> 1719.7 | G11: =SUM(G12:G14) -> 779.9 | H11: =SUM(H12:H14) -> 691.4 | I11: =SUM(I12:I14) -> 791.7 | ... M11: =SUM(M12:M14) -> 958.32 | N11: =SUM(B11:M11) -> 9488.92
A12: Bank Charges | B12: 123.9 | C12: 11.8 | D12: 17.7 | E12: 159.3 | F12: 1282 | G12: 342.2 | H12: 253.7 | I12: 354 | J12: =354+29.5 -> 383.5 | K12: 354 | L12: =K12*1.1 -> 389.4 | M12: =L12*1.1 -> 428.34
A13: Interest on Bank loan | B13: 437.7 | C13: 437.7 | D13: 437.7 | E13: 437.7 | F13: 437.7 | G13: 437.7 | H13: 437.7 | I13: 437.7 | J13: 437.7 | K13: 438 | L13: =K13*1.1 -> 481.8 | M13: =L13*1.1 -> 529.98
L14: =K14*1.1 -> 0 | M14: =L14*1.1 -> 0
A15: HR Expenses | B15: =SUM(B16:B21) -> 315569 | C15: =SUM(C16:C21) -> 333814 | D15: =SUM(D16:D21) -> 284197 | E15: =SUM(E16:E21) -> 313931 | F15: =SUM(F16:F21) -> 329926 | G15: =SUM(G16:G21) -> 353303 | H15: =SUM(H16:H21) -> 356918 | I15: =SUM(I16:I21) -> 371259 | ... M15: =SUM(M16:M21) -> 379338.63 | N15: =SUM(B15:M15) -> 4083442.9
A16: Employee Salaries | B16: 280600 | C16: 293800 | D16: 256000 | E16: 276246 | F16: 292632 | G16: 306914 | H16: 299787 | I16: 299654 | J16: 291074 | K16: 256877 | L16: =K16*1.1 -> 282564.7 | M16: =L16*1.1 -> 310821.17
A17: Incentives | B17: 34969 | C17: 40014 | D17: 28197 | E17: 37685 | F17: 37294 | G17: 41954 | H17: 57131 | I17: 70195 | J17: 80757 | K17: 45497 | L17: =K17*1.1 -> 50046.7 | M17: =L17*1.1 -> 55051.37
A18: Partner Remuneration | L18: =K18*1.1 -> 0 | M18: =L18*1.1 -> 0
A19: PF Admin Charges | G19: 4435 | I19: 1410 | L19: =K19*1.1 -> 0 | M19: =L19*1.1 -> 0
A20: Stipend | J20: 15000 | K20: 11129 | L20: =K20*1.1 -> 12241.9 | M20: =L20*1.1 -> 13466.09
L21: =K21*1.1 -> 0 | M21: =L21*1.1 -> 0
A22: Marketing & Ads | B22: =B23+B24 -> 8054 | C22: =C23+C24 -> 14232 | D22: =D23+D24 -> 5015 | E22: =E23+E24 -> 11016 | F22: =F23+F24 -> 5000 | G22: =G23+G24 -> 5000 | H22: =H23+H24 -> 8070 | I22: =I23+I24 -> 0 | ... M22: =M23+M24 -> 4840 | N22: =SUM(B22:M22) -> 72127
A23: Meta / Instagram | B23: 8054 | C23: 14232 | D23: 5015 | E23: 11016 | F23: 5000 | G23: 5000 | H23: 8070 | J23: 2500 | K23: 4000 | L23: =K23*1.1 -> 4400 | M23: =L23*1.1 -> 4840
A24: Events / Exhibitions | L24: =K24*1.1 -> 0 | M24: =L24*1.1 -> 0
A25: Professional Service Charges | B25: 24000 | C25: 24000 | D25: 24000 | E25: =24000+17700 -> 41700 | F25: 24000 | G25: 24000 | H25: =24000+23600+4500 -> 52100 | I25: 24000 | J25: 33440 | K25: 24000 | L25: 24000 | M25: 24000 | N25: =SUM(B25:M25) -> 343240
A26: Rates & Taxes | F26: 70 | G26: -560.89 | H26: 16.06 | I26: 7.31 | N26: =SUM(B26:M26) -> -467.52
A27: Repairs & Maintenance | B27: 57062 | C27: 171460 | D27: 16308 | E27: 86738 | F27: 49624 | G27: 116867 | H27: 18611 | I27: 31568 | J27: 17866 | K27: 31713 | L27: =K27*1.5 -> 47569.5 | M27: =L27*1.5 -> 71354.25 | N27: =SUM(B27:M27) -> 716740.75
A28: Misc. Expenses | B28: 2500 | N28: =SUM(B28:M28) -> 2500
A29: Grand Total | B29: =B3+B11+B15+B22+B27+B25+B28+B26 -> 420850.6 | C29: =C3+C11+C15+C22+C27+C25+C28+C26 -> 587598.5 | D29: =D3+D11+D15+D22+D27+D25+D28+D26 -> 421648.4 | E29: =E3+E11+E15+E22+E27+E25+E28+E26 -> 487783 | F29: =F3+F11+F15+F22+F27+F25+F28+F26 -> 436702.7 | G29: =G3+G11+G15+G22+G27+G25+G28+G26 -> 532791.01 | H29: =H3+H11+H15+H22+H27+H25+H28+H26 -> 511955.18 | I29: =I3+I11+I15+I22+I27+I25+I28+I26 -> 472405.01 | ... M29: =M3+M11+M15+M22+M27+M25+M28+M26 -> 633135.12 | N29: =SUM(B29:M29) -> 6052303.9

Sheet Cashflow Projection
B1: THOTA HOSPITALITY LLP
B2: Projections F.Y. 2025-26
B5: Projection Statement of Cash Flow | C5: 2025-26
B6: Advance received during the month against order | C6: 0.4
B7: Balance will be received 45 days from Invoice date | C7: 0.6
B9: Particulars | C9: Apr | D9: May | E9: Jun | F9: Jul | G9: Aug | H9: Sep | I9: Oct | J9: Nov | K9: Dec | L9: Jan | M9: Feb | N9: Mar | O9: Total
B10: Revenues & Inflow
B11: Revenue from Sale of Goods | C11: =505074-(C13+C12) -> 197625 | D11: =1479643-(D12+D13) -> 476037 | E11: =1184157-E12 -> 1184157 | F11: =750355.65-F12 -> 750355.65 | G11: =983496-G12 -> 983496 | H11: =1891311-H12 -> 1891311 | I11: =2146465.92+10034-55652 -> 2100847.9 | J11: =('P&L Detailed'!H5*'Cashflow Projection'!C7)+('P&L Detailed'!I5*'Cashflow Projection'!C6) -> 124349.6 | K11: =('P&L Detailed'!I5*'Cashflow Projection'!C7)+('P&L Detailed'!J5*'Cashflow Projection'!C6) -> 124114.2 | L11: =('P&L Detailed'!J5*'Cashflow Projection'!C7)+('P&L Detailed'!K5*'Cashflow Projection'!C6) -> 78477.4 | M11: =('P&L Detailed'!K5*'Cashflow Projection'!C7)+('P&L Detailed'!L5*'Cashflow Projection'!C6) -> 101584 | N11: =('P&L Detailed'!L5*'Cashflow Projection'!C7)+('P&L Detailed'!M5*'Cashflow Projection'!C6) -> 132059.2 | O11: =SUM(C11:N11) -> 8144414
B12: Services & Solutions | C12: ='P&L Detailed'!B9 | D12: ='P&L Detailed'!C9 | E12: ='P&L Detailed'!D9 | F12: ='P&L Detailed'!E9 | G12: ='P&L Detailed'!F9 | H12: ='P&L Detailed'!G9 | I12: ='P&L Detailed'!H9 | J12: ='P&L Detailed'!I9 | ... N12: ='P&L Detailed'!M9 | O12: =SUM(C12:N12) -> 0
B13: Previous Year AR | C13: 307449 | D13: 1003606 | O13: =SUM(C13:N13) -> 1311055
B14: Fixed Deposits | D14: 2500000 | O14: =SUM(C14:N14) -> 2500000
B15: Secured/Unsecured Loan | I15: 400000 | J15: 500000 | O15: =SUM(C15:N15) -> 900000
B16: Other Cash Receipts / Refunds | C16: =515932-(C11+C13+C12) -> 10858 | D16: =4167432-SUM(D11:D15) -> 187789 | E16: =1321271-(E11+E13+E12+#REF!+E14+E15) -> #REF! | F16: =906683.61-SUM(F11:F15) -> 156327.96 | G16: 400295 | H16: =1903078-(SUM(H11:H15)) -> 11767 | I16: 2021 | O16: =SUM(C16:N16) -> #REF!
B17: Total Inflow | C17: =SUM(C11:C16) -> 515932 | D17: =SUM(D11:D16) -> 4167432 | E17: =SUM(E11:E16) -> #REF! | F17: =SUM(F11:F16) -> 906683.61 | G17: =SUM(G11:G16) -> 1383791 | H17: =SUM(H11:H16) -> 1903078 | I17: =SUM(I11:I16) -> 2502868.9 | J17: =SUM(J11:J16) -> 624349.6 | ... O17: =SUM(O11:O16) -> #REF!
B18: Payments
B19: Purchases (COGS) | C19: =#REF! -> #REF! | D19: =#REF! -> #REF! | E19: =#REF! -> #REF! | F19: =#REF! -> #REF! | G19: =#REF! -> #REF! | H19: =#REF! -> #REF! | I19: =#REF! -> #REF! | J19: 300000 | K19: =('P&L Detailed'!I10*20%)+('P&L Detailed'!J10*80%) -> 303250.8 | L19: =('P&L Detailed'!J10*20%)+('P&L Detailed'!K10*80%) -> 282431.2 | M19: =('P&L Detailed'!K10*20%)+('P&L Detailed'!L10*80%) -> 338438.16 | N19: =('P&L Detailed'!L10*20%)+('P&L Detailed'!M10*80%) -> 439969.61 | O19: =SUM(C19:N19) -> #REF!
B20: Direct Expenses | C20: ='P&L Detailed'!B15 -> 35008 | D20: ='P&L Detailed'!C15 -> 34233 | E20: ='P&L Detailed'!D15 -> 29919 | F20: ='P&L Detailed'!E15 -> 30792 | G20: ='P&L Detailed'!F15 -> 29948 | H20: ='P&L Detailed'!G15 -> 27828 | I20: ='P&L Detailed'!H15 -> 19090 | J20: ='P&L Detailed'!I15 -> 21450 | ... N20: ='P&L Detailed'!M15 -> 57481.97 | O20: =SUM(C20:N20) -> 396383.87
B21: Previous Year AP | C21: =251323+131910 -> 383233 | O21: =SUM(C21:N21) -> 383233
B22: Sub Total | C22: =SUM(C19:C21) -> #REF! | D22: =SUM(D19:D21) -> #REF! | E22: =SUM(E19:E21) -> #REF! | F22: =SUM(F19:F21) -> #REF! | G22: =SUM(G19:G21) -> #REF! | H22: =SUM(H19:H21) -> #REF! | I22: =SUM(I19:I21) -> #REF! | J22: =SUM(J19:J21) -> 321450 | ... N22: =SUM(N19:N21) -> 497451.58 | O22: =SUM(C22:N22) -> #REF!
B24: Indirect Costs
B25: Advertisement/Marketing | C25: =#REF! -> #REF! | D25: =#REF! -> #REF! | E25: =#REF! -> #REF! | F25: =#REF! -> #REF! | G25: =#REF! -> #REF! | H25: =#REF! -> #REF! | I25: =#REF! -> #REF! | J25: =#REF! -> #REF! | ... N25: =#REF! -> #REF! | O25: =SUM(C25:N25) -> #REF!
B26: Office & Administrative Overheads | C26: =#REF! -> #REF! | D26: =#REF! -> #REF! | E26: =#REF! -> #REF! | F26: =#REF! -> #REF! | G26: =#REF! -> #REF! | H26: =#REF! -> #REF! | I26: =#REF!+37093 -> #REF! | J26: =#REF! -> #REF! | K26: =#REF! -> #REF! | L26: =#REF! -> #REF! | M26: =#REF! -> #REF! | N26: =#REF! -> #REF! | O26: =SUM(C26:N26) -> #REF!
B27: Payroll Expenses | C27: =#REF! -> #REF! | D27: =#REF! -> #REF! | E27: =#REF! -> #REF! | F27: =#REF! -> #REF! | G27: =#REF! -> #REF! | H27: =#REF! -> #REF! | I27: =#REF! -> #REF! | J27: =#REF! -> #REF! | ... N27: =#REF! -> #REF! | O27: =SUM(C27:N27) -> #REF!
B28: Rates & Taxes | C28: =#REF! -> #REF! | D28: =#REF! -> #REF! | E28: =#REF! -> #REF! | F28: =#REF! -> #REF! | G28: =#REF! -> #REF! | H28: =#REF! -> #REF! | I28: =#REF! -> #REF! | J28: =#REF! -> #REF! | ... N28: =#REF! -> #REF! | O28: =SUM(C28:N28) -> #REF!
B29: R&D | C29: =#REF! -> #REF! | D29: =#REF! -> #REF! | E29: =#REF! -> #REF! | F29: =#REF! -> #REF! | G29: =#REF! -> #REF! | H29: =#REF! -> #REF! | I29: =#REF! -> #REF! | J29: =#REF! -> #REF! | ... N29: =#REF! -> #REF! | O29: =SUM(C29:N29) -> #REF!
B30: Travelling Expense | C30: =#REF! -> #REF! | D30: =#REF! -> #REF! | E30: =#REF! -> #REF! | F30: =#REF! -> #REF! | G30: =#REF! -> #REF! | H30: =#REF! -> #REF! | I30: =#REF! -> #REF! | J30: =#REF! -> #REF! | ... N30: =#REF! -> #REF! | O30: =SUM(C30:N30) -> #REF!
B31: Foreign Exchange Gain/Loss | C31: =#REF! -> #REF! | D31: =#REF! -> #REF! | E31: =#REF! -> #REF! | F31: =#REF! -> #REF! | G31: =#REF! -> #REF! | H31: =#REF! -> #REF! | I31: =#REF! -> #REF! | J31: =#REF! -> #REF! | ... N31: =#REF! -> #REF! | O31: =SUM(C31:N31) -> #REF!
B32: Freight Outward | C32: =#REF! -> #REF! | D32: =#REF! -> #REF! | E32: =#REF! -> #REF! | F32: =#REF! -> #REF! | G32: =#REF! -> #REF! | H32: =#REF! -> #REF! | I32: =#REF! -> #REF! | J32: =#REF! -> #REF! | ... N32: =#REF! -> #REF! | O32: =SUM(C32:N32) -> #REF!
B33: Professional Service Charges | C33: =#REF! -> #REF! | D33: =#REF! -> #REF! | E33: =#REF! -> #REF! | F33: =#REF! -> #REF! | G33: =#REF! -> #REF! | H33: =#REF! -> #REF! | I33: =#REF! -> #REF! | J33: =#REF! -> #REF! | ... N33: =#REF! -> #REF! | O33: =SUM(C33:N33) -> #REF!
B34: Bank Interest | C34: ='P&L Detailed'!B42 -> 561.6 | D34: ='P&L Detailed'!C42 -> 449.5 | E34: ='P&L Detailed'!D42 -> 455.4 | F34: ='P&L Detailed'!E42 -> 597 | G34: ='P&L Detailed'!F42 -> 1719.7 | H34: ='P&L Detailed'!G42 -> 779.9 | I34: ='P&L Detailed'!H42 -> 691.4 | J34: ='P&L Detailed'!I42 -> 791.7 | ... N34: ='P&L Detailed'!M42 -> 958.32 | O34: =SUM(C34:N34) -> 9488.92
B36: Capital Purchases (exl. GST) | C36: =23500+11813+11008 -> 46321 | D36: =70745+7623+6900 -> 85268 | F36: =22860+25000+18414 -> 66274 | G36: =10000+1694 -> 11694 | O36: =SUM(C36:N36) -> 209557
B37: Rental Deposit / Other Advances | I37: 60000 | O37: =SUM(C37:N37) -> 60000
O38: =SUM(C38:N38) -> 0
B39: Loan Repayment | O39: =SUM(C39:N39) -> 0
B40: Partner's Loan | O40: =SUM(C40:N40) -> 0
B41: Secured/Unsecured/Corporate Loans | C41: 43980 | F41: 20000 | I41: 400000 | O41: =SUM(C41:N41) -> 463980
O42: =SUM(C42:N42) -> 0
B43: Statutory Payments | O43: =SUM(C43:N43) -> 0
B44: Direct & Indirect Taxes | C44: 38754 | D44: 0 | E44: 0 | F44: 0 | H44: =8455+50000 -> 58455 | I44: =8526+59516 -> 68042 | O44: =SUM(C44:N44) -> 165251
B45: HR Compliances | O45: =SUM(C45:N45) -> 0
...

Sheet Revenue-Detailed
B1: Date | C1: Party Name | D1: GSTIN | E1: Bill Date | F1: Number | G1: Revenue Centres | H1: Product | I1: HSN/SAC | J1: Quantity | K1: Unit | L1: Invoice lines/Unit Price | M1: Subtotal
A2: 45748 | B2: 45777 | C2: Continental Automotive Components (India) Private Limited | E2: 45777 | F2: INV/2526/FW18 | G2: CONSUMABLES | H2: PLA+ Black 3D Printing Filament 1.75mm 1kg | I2: 84431100 | J2: 1 | K2: Units | L2: 1460 | M2: 1460
A3: 45748 | G3: AMC Sales (Spares and Service Visits) | H3: Shipping Charges | I3: 9968 | J3: 1 | K3: Units | L3: 500 | M3: 500
A4: 45748 | B4: 45770 | C4: 3D Works Design Solutions | D4: 03AANPU7335B1ZQ | E4: 45770 | F4: INV/2526/FW17 | G4: AMC Sales (Spares and Service Visits) | H4: PTFE Tube ID2 OD4 | I4: 8477 | J4: 0.3 | K4: m | L4: 900 | M4: 270
A5: 45748 | G5: AMC Sales (Spares and Service Visits) | H5: Thermistor 100k NTC | I5: 8477 | J5: 3 | K5: Units | L5: 300 | M5: 900
A6: 45748 | G6: AMC Sales (Spares and Service Visits) | H6: 24V 40W Heater Cartridge | I6: 8477 | J6: 3 | K6: Units | L6: 350 | M6: 1050
A7: 45748 | G7: AMC Sales (Spares and Service Visits) | H7: 0.4mm Hardened Steel V6 Nozzle Tip | I7: 8477 | J7: 2 | K7: Units | L7: 320 | M7: 640
A8: 45748 | G8: AMC Sales (Spares and Service Visits) | H8: Hotend Service Charges | I8: 998719 | J8: 3 | K8: Units | L8: 400 | M8: 1200
A9: 45748 | G9: AMC Sales (Spares and Service Visits) | H9: Shipping Charges | I9: 9968 | J9: 1 | K9: Units | L9: 350 | M9: 350
A10: 45748 | B10: 45769 | C10: Indian Institute of Science- Dr Hardik J Pandya | D10: 29AAATI1501J2ZV | E10: 45769 | F10: INV/2526/FW16 | G10: 3D printing Service | H10: 3D Printing FDM Manufacturing Service | I10: 3926 | J10: 1 | K10: Units | L10: 2425 | M10: 2425
A11: 45748 | G11: 3D printing Service | H11: 3D Printing FDM Manufacturing Service | I11: 3926 | J11: 1 | K11: Units | L11: 2461 | M11: 2461
A12: 45748 | G12: AMC Sales (Spares and Service Visits) | H12: Shipping Charges | I12: 9968 | J12: 1 | K12: Units | L12: 200 | M12: 200
A13: 45748 | B13: 45769 | C13: Vigyan Ashram | E13: 45769 | F13: INV/2526/FW15 | G13: AMC Sales (Spares and Service Visits) | H13: V6 Lite Hotend 24V (Brass 0.4mm) | I13: 8477 | J13: 1 | K13: Units | L13: 4500 | M13: 4500
A14: 45748 | G14: AMC Sales (Spares and Service Visits) | H14: Shipping Charges | I14: 9968 | J14: 1 | K14: Units | L14: 350 | M14: 350
A15: 45748 | B15: 45769 | C15: Indian Institute of Technology Tirupati | D15: 37AAAAI9917R3ZS | E15: 45769 | F15: INV/2526/FW14 | G15: AMC Sales (Spares and Service Visits) | H15: V6 Lite Hotend 24V (Brass 0.4mm) | I15: 8477 | J15: 1 | K15: Units | L15: 4800 | M15: 4800
A16: 45748 | G16: AMC Sales (Spares and Service Visits) | H16: Carriage PCB Julia- SF | I16: 8477 | J16: 1 | K16: Units | L16: 740 | M16: 740
A17: 45748 | G17: AMC Sales (Spares and Service Visits) | H17: 30mm Fan 24V | I17: 8477 | J17: 1 | K17: Units | L17: 450 | M17: 450
A18: 45748 | G18: AMC Sales (Spares and Service Visits) | H18: 20 pin 50cm reverse FFC | I18: 8477 | J18: 1 | K18: Units | L18: 410 | M18: 410
A19: 45748 | G19: AMC Sales (Spares and Service Visits) | H19: Carriage PCB Acrylic - Ext. | I19: 8477 | J19: 1 | K19: Units | L19: 10 | M19: 10
A20: 45748 | G20: AMC Sales (Spares and Service Visits) | H20: Service Visit Charge | I20: 998719 | J20: 1 | K20: Units | L20: 2200 | M20: 2200
A21: 45748 | G21: AMC Sales (Spares and Service Visits) | H21: 4010 Blower Fan | I21: 8477 | J21: 2 | K21: Units | L21: 600 | M21: 1200
A22: 45748 | G22: AMC Sales (Spares and Service Visits) | H22: Spool Holder for Julia Pro | I22: 8477 | J22: 1 | K22: Units | L22: 500 | M22: 500
A23: 45748 | G23: AMC Sales (Spares and Service Visits) | H23: PTFE Tube ID2 OD4 | I23: 8477 | J23: 70 | K23: cm | L23: 9 | M23: 630
A24: 45748 | G24: AMC Sales (Spares and Service Visits) | H24: Shipping Charges | I24: 9968 | J24: 1 | K24: Units | L24: 300 | M24: 300
A25: 45748 | G25: AMC Sales (Spares and Service Visits) | H25: Field Service | I25: 998719 | J25: 1 | K25: Hours | L25: 4000 | M25: 4000
A26: 45748 | B26: 45768 | C26: Amace Solutions Pvt. Ltd. | D26: 29AARCA3445M1Z1 | E26: 45768 | F26: INV/2526/FW13 | G26: 3D printing Service | H26: 3D Printing FDM Manufacturing Service | I26: 3926 | J26: 1 | K26: Units | L26: 2872.8 | M26: 2872.8
A27: 45748 | B27: 45765 | C27: Continental Automotive Components (India) Pvt.Ltd - Technical Centre | D27: 29AAKCS9578C1ZP | E27: 45765 | F27: INV/2526/FW12 | G27: CONSUMABLES | H27: PLA+ Black 3D Printing Filament 1.75mm 1kg | I27: 84431100 | J27: 2 | K27: Units | L27: 1460 | M27: 2920
A28: 45748 | G28: AMC Sales (Spares and Service Visits) | H28: Shipping Charges | I28: 9968 | J28: 1 | K28: Units | L28: 500 | M28: 500
A29: 45748 | B29: 45765 | C29: Guide3D Tech (OPC) Pvt Ltd | D29: 24AAICG4958J1Z8 | E29: 45765 | F29: INV/2526/FW11 | G29: 3D Printer Sales | H29: Twin Dragon 600 | I29: 84779000 | J29: 1 | K29: Units | L29: 127590 | M29: 127590
A30: 45748 | G30: 3D Printer Sales | H30: Shipping Charges | I30: 9968 | J30: 1 | K30: Units | L30: 8000 | M30: 8000
A31: 45748 | G31: AMC Sales (Spares and Service Visits) | J31: 0 | L31: 0 | M31: 0
A32: 45748 | B32: 45762 | C32: Auma India Pvt Ltd | D32: 29AABCA1342F1Z4 | E32: 45762 | F32: INV/2526/FW10 | G32: CONSUMABLES | H32: PLA+ White 3D Printing Filament 1.75mm 1kg | I32: 8443 | J32: 3 | K32: Units | L32: 1400 | M32: 4200
A33: 45748 | B33: 45757 | C33: Technoventor Innovations Private Limited | D33: 27AAFCT9460K1ZR | E33: 45757 | F33: INV/2526/FW9 | G33: AMC Sales (Spares and Service Visits) | H33: Pei powder coated 260 | I33: 8477 | J33: 1 | K33: Units | L33: 2500 | M33: 2500
A34: 45748 | G34: AMC Sales (Spares and Service Visits) | H34: Shipping Charges | I34: 9968 | J34: 1 | K34: Units | L34: 350 | M34: 350
A35: 45748 | B35: 45757 | C35: M. SUDHA M Sudha Saravanan | E35: 45757 | F35: FOC/2025/00011 | G35: AMC Sales (Spares and Service Visits) | H35: SMPS 24V 240W | I35: 8477 | J35: 1 | K35: Units | L35: 1200 | M35: 0
A36: 45748 | G36: AMC Sales (Spares and Service Visits) | J36: 1 | L36: 0 | M36: 0
A37: 45748 | B37: 45757 | C37: L. DAVID WILLIAM RAJ (Faculty) | E37: 45757 | F37: FOC/2025/00010 | G37: AMC Sales (Spares and Service Visits) | H37: AMC | I37: 998719 | J37: 1 | K37: Units | L37: 0 | M37: 0
A38: 45748 | B38: 45756 | C38: GREAVES ELECTRIC MOBILITY PRIVATE LIMITED-BLR | D38: 29AAHCA0665K1ZF | E38: 45756 | F38: INV/2526/FW8 | G38: AMC Sales (Spares and Service Visits) | H38: Hotend Service Charges | I38: 998719 | J38: 1 | K38: Units | L38: 400 | M38: 400
A39: 45748 | B39: 45756 | C39: Sarga Additive Manufacturing | D39: 08ABBCS0837Q1ZV | E39: 45756 | F39: INV/2526/FW7 | G39: 3D Printer Sales | H39: Snowflake V2 | I39: 8477 | J39: 1 | K39: Units | L39: 55000 | M39: 35002
A40: 45748 | G40: AMC Sales (Spares and Service Visits) | J40: 0 | L40: 0 | M40: 0
...

Sheet Revenue Projection
A1: Expected Closure | B1: Deal Owner | C1: Amount | D1: Deal Name | E1: Machine Name | F1: Account Name | G1: Stage | H1: Probability (%) | I1: Probability () | J1: Next Step | K1: Lead Source | L1: Description | M1: Contact Name | N1: Expected Revenue | O1: Currency | P1: Exchange Rate | Q1: Lead Conversion Time | R1: Sales Cycle Duration | S1: Overall Sales Duration | T1: Lead Generated By | U1: Sale Channel | V1: Customer Requirement(s)
A2: Q2 | B2: Vijay Varada | C2: 2400000 | D2: INA - Kannur | E2: Volterra | G2: Negotiation / Tendering | H2: 50 | I2: =C2*H2% -> 1200000 | J2: Expecting tender opening 2nd week Aug | K2: Website | L2: Volterra + Accessories | M2: Dadi Ravikanth | N2: 1200000 | O2: INR | P2: 1 | Q2: 0 | R2: 452 | S2: 452
A3: Q2 | B3: Geo Tijo | D3: 3d printer requirment | E3: Twin Dragon 600 | F3: colorz india pvt ltd | G3: New Lead | H3: 0 | M3: Sunil sethi | O3: INR | P3: 1
A4: Q2 | B4: Geo Tijo | C4: 275000 | D4: Q1'25 - Dragon400 | E4: Julia 250 | F4: Mother India farming | G4: Sales Qualified Lead | H4: 5 | K4: Direct Prospecting | M4: Sudharshan R Hegde | N4: 13750 | O4: INR | P4: 1 | R4: 29 | S4: 29 | U4: Direct
A5: Q2 | B5: Geo Tijo | C5: 1450000 | D5: MIT Manipal TD600 + Ecosystem Purchase | E5: Twin Dragon 600 | F5: Manipal Institute of Technology | G5: PO Received | H5: 100 | I5: =C5*H5% -> 1450000 | J5: Waiting for confirmation of the order from Purchase Dept. | M5: suhas.nayak | N5: 1450000 | O5: INR | P5: 1 | R5: 90 | S5: 90 | T5: Upselling | U5: Direct | V5: 3D Printer Hardware;Consumables;Accessories
A6: Q2 | B6: Geo Tijo | C6: 600000 | D6: UBDT - J250 | E6: Julia 250 | F6: University BDT College of Engineering (UBDT) | G6: Negotiation / Tendering | H6: 50 | I6: =C6*H6% -> 300000 | J6: Awaiting opening of tender by July last week | K6: Direct Prospecting | M6: Basavaraj S | N6: 300000 | O6: INR | P6: 1 | U6: Direct
A7: Q2 | B7: Geo Tijo | C7: 800000 | D7: Twin Dragon: Jigs & Fixtures Division | E7: Twin Dragon | F7: TATA ELECTRONICS PRIVATE LIMITED | G7: Negotiation / Tendering | H7: 50 | I7: =C7*H7% -> 400000 | J7: 14th July purchase department will confirm on Trials and PO date | K7: Direct Prospecting | M7: Santosh S. | N7: 400000 | O7: INR | P7: 1 | R7: 129 | S7: 129 | T7: Vijay | U7: Direct | V7: 3D Printer Hardware
A8: Q2 | B8: Vijay Varada | C8: 300000 | D8: Dragon 400 | F8: Soen Audio | G8: Demo / Samples Done | H8: 15 | J8: Send Sampling | K8: Direct Prospecting | M8: Hari Seedhar | N8: 45000 | O8: INR | P8: 1 | T8: Vijay | U8: Direct
A9: Q2 | B9: Vijay Varada | C9: 390000 | D9: Pannaga - D 500 | F9: Pannaga NextechÂ PvtÂ Ltd | G9: Re-Evaluate | H9: 0 | M9: Sarala R. | N9: 0 | O9: INR | P9: 1 | U9: Direct
A10: Q2 | B10: Geo Tijo | C10: 965000 | D10: TD 600 | F10: Accurel India Pvt Ltd | G10: Demo / Samples Done | H10: 15 | J10: In person demo @ factory send PETg Part | M10: Dhanush Accurel | N10: 144750 | O10: INR | P10: 1 | U10: Direct | V10: 3D Printer Hardware
A11: Q2 | B11: Vijay Varada | C11: 680000 | D11: IIIT Kurnool Dragon 700 | F11: IIIT Kurnool | G11: Sales Qualified Lead | H11: 5 | J11: GEM has to be set up with proper golden parameters so that we are L1 | K11: Channel Partner | M11: Yogendra Srivastava | N11: 34000 | O11: INR | P11: 1 | T11: Channel Partner | U11: Channel Partner | V11: 3D Printer Hardware
A12: Q2 | B12: Vijay Varada | C12: 400000 | D12: Manipal Bangalore 3D Printer | F12: MAHE Bengaluru | G12: Proposal / Quote Sent | H12: 20 | J12: Follow up today on Aug 4th | K12: Direct Prospecting | M12: Sravani . | N12: 80000 | O12: INR | P12: 1 | R12: 53 | S12: 53 | T12: Vijay Raghav Varada | U12: Direct | V12: 3D Printer Hardware
A13: Q2 | B13: Vijay Varada | C13: 1000000 | D13: Honda MotorCycle and Scooters India Pvt Ltd | E13: Twin Dragon 600 | F13: Honda MotorCycle and Scooters India Pvt Ltd | G13: Awaiting PO | H13: 80 | I13: =C13*H13% -> 800000 | K13: Event | M13: Rajath Juneja | N13: 800000 | O13: INR | P13: 1 | Q13: 77 | R13: 52 | S13: 129 | U13: Direct | V13: 3D Printer Hardware;Consulting;Training/Onboarding;Accessories
A14: Q2 | B14: Geo Tijo | C14: 700000 | D14: CMTI Paste Extruder | F14: CMTI (Central Manufacturing Technology Institute) | G14: Delivered & Installed | H14: 100 | I14: =C14*H14% -> 700000 | J14: Follow-up on next steps | K14: Direct Prospecting | M14: Manju BN | N14: 700000 | O14: INR | P14: 1 | U14: Direct | V14: Custom 3D Printer;Consulting
A15: Q2 | B15: Geo Tijo | C15: 400000 | D15: Kalasalingam University TD 300 | F15: Kalasalingam University | G15: Re-Evaluate | H15: 0 | M15: Venkat Global | N15: 0 | O15: INR | P15: 1 | U15: Channel Partner | V15: 3D Printer Hardware
A16: Q2 | B16: Geo Tijo | C16: 400000 | D16: CMTI - Food 3d Printer | E16: Other 3D Printer | F16: CMTI (Central Manufacturing Technology Institute) | G16: PO Received | H16: 100 | I16: =C16*H16% -> 400000 | M16: Pradyumma cmti | N16: 400000 | O16: INR | P16: 1 | U16: Direct | V16: 3D Printer Hardware
A17: Q2 | B17: Geo Tijo | C17: 125000 | D17: Filament Dryer | F17: uno minda - kamal | G17: Closed Lost | H17: 0 | L17: need to push him for the same | M17: kamal uno | N17: 0 | O17: INR | P17: 1 | U17: Direct | V17: 3D Printer Hardware
A18: Q2 | B18: Geo Tijo | C18: 750000 | D18: infinite traders - TD 600 | F18: infinite Traders | G18: Sales Qualified Lead | H18: 5 | M18: Raj Kiran | N18: 37500 | O18: INR | P18: 1 | U18: Direct | V18: 3D Printer Hardware
A19: Q2 | B19: Geo Tijo | C19: 300000 | D19: LAT Aerosapce | E19: Dragon | F19: LAT Aerosapce | G19: Delivered & Installed | H19: 100 | I19: =C19*H19% -> 300000 | K19: Website | M19: Yaswanth Namburi | N19: 300000 | O19: INR | P19: 1 | Q19: 1 | U19: Direct | V19: 3D Printer Hardware
A20: Q2 | B20: Geo Tijo | C20: 150000 | D20: Beoing fdm | F20: Beoing | G20: Sales Qualified Lead | H20: 5 | M20: Shamik beoing | N20: 7500 | O20: INR | P20: 1 | U20: Direct | V20: 3D Printer Hardware
A21: Q2 | B21: Geo Tijo | D21: iisc fsid | F21: IISc - SID | G21: Sales Qualified Lead | H21: 5 | L21: machine not fixed | M21: Raj Waghray | O21: INR | P21: 1 | U21: Direct | V21: 3D Printer Hardware
A22: Q2 | B22: Geo Tijo | D22: AKSI AI AEROSPACE AND AGRI TECHNOLOGY VENTURES PVT LTD | F22: AKSI AI AEROSPACE AND AGRI TECHNOLOGY VENTURES PVT LTD | G22: Closed Lost | H22: 0 | K22: Website | M22: Jayant Pampana | O22: INR | P22: 1 | Q22: 1 | U22: Direct | V22: 3D Printer Hardware
A23: Q2 | B23: Vijay Varada | D23: Wonder Electricals Ltd | F23: Wonder Electricals Ltd | G23: Sales Qualified Lead | H23: 5 | K23: Website | M23: yogesh sahni | O23: INR | P23: 1 | Q23: 3 | U23: Direct | V23: 3D Printer Hardware
A24: Q2 | B24: Geo Tijo | D24: Vikas | G24: Sales Qualified Lead | H24: 5 | K24: Chat | M24: Vikas | O24: INR | P24: 1 | Q24: 4 | U24: Direct | V24: 3D Printer Hardware
A25: Q2 | B25: Geo Tijo | D25: Farooq Ahmed | G25: Sales Qualified Lead | H25: 5 | K25: Chat | M25: Farooq Ahmed | O25: INR | P25: 1 | Q25: 3 | U25: Direct | V25: 3D Printer Hardware
A26: Q2 | B26: Geo Tijo | D26: Manju Kriplani | G26: Sales Qualified Lead | H26: 5 | K26: Chat | M26: Manju Kriplani | O26: INR | P26: 1 | Q26: 2 | U26: Direct | V26: Jobwork
A27: Q2 | B27: Geo Tijo | C27: 13216 | D27: manipal Manipal Academy of Higher Education | E27: AMC | F27: Manipal Academy of Higher Education (MAHE) | G27: PO Received | H27: 100 | I27: =C27*H27% -> 13216 | J27: Need amended PO as shipping charges need to include. | M27: suhas.nayak | N27: 13216 | O27: INR | P27: 1 | U27: Direct | V27: Consumables
A28: Q2 | B28: Impa HL | C28: 3776 | D28: ETOE Interconnections Pvt Ltd. | E28: Fracktory | F28: Sachin Biradar | G28: Payment Complete | H28: 100 | I28: =C28*H28% -> 3776 | M28: Sachin Biradar | N28: 3776 | O28: INR | P28: 1 | U28: Direct | V28: Jobwork
A29: Q2 | B29: Geo Tijo | C29: 10631 | D29: Involine Technologies | F29: Ravi | G29: Closed Lost | H29: 0 | M29: ravi . | N29: 0 | O29: INR | P29: 1 | U29: Direct | V29: Jobwork
A30: Q2 | B30: Vijay Varada | C30: 322140 | D30: TVS Motor Company | F30: TVS Motor Company | G30: Proposal / Quote Sent | H30: 20 | M30: TVS Motor Company | N30: 64428 | O30: INR | P30: 1 | U30: Direct | V30: Jobwork
A31: Q2 | B31: Geo Tijo | C31: 93119.7 | D31: SIDDHARTH MODEL SPORTS PRIVATE LIMITED | F31: SIDDHARTH MODEL SPORTS PRIVATE LIMITED | G31: Proposal / Quote Sent | H31: 20 | J31: Need follow up | M31: SIDDHARTH MODEL SPORTS PRIVATE LIMITED | N31: 18623.94 | O31: INR | P31: 1 | U31: Direct | V31: Jobwork
A32: Q2 | B32: Geo Tijo | C32: 137000 | D32: Gaurang | G32: Sales Qualified Lead | H32: 5 | K32: Chat | M32: Gaurang | N32: 6850 | O32: INR | P32: 1 | Q32: 2 | U32: Direct | V32: 3D Printer Hardware
A33: Q2 | B33: Geo Tijo | C33: 403088 | D33: ADIANCE TECHNOLOGIES PRIVATE LIMITED | F33: ADIANCE TECHNOLOGIES PRIVATE LIMITED | G33: Proposal / Quote Sent | H33: 20 | M33: ADIANCE TECHNOLOGIES PRIVATE LIMITED | N33: 80617.6 | O33: INR | P33: 1 | U33: Direct | V33: Jobwork
A34: Q3 | B34: Vijay Varada | C34: 2800000 | D34: Multi Material DLP Printer Software | F34: CMET (Center for Materials for Electronics Technology) | G34: Proposal / Quote Sent | H34: 20 | J34: Followup on tender release | K34: Partner | M34: Shany Joseph CMET | N34: 560000 | O34: INR | P34: 1 | U34: Direct
A35: Q3 | B35: Sanjay Narayan | C35: 390000 | D35: Kishore TD500 | F35: Kishore | G35: Sales Qualified Lead | H35: 5 | K35: Event | M35: Kishore T | N35: 19500 | O35: INR | P35: 1 | T35: Imtex Lead | U35: Direct
A36: Q3 | B36: Geo Tijo | C36: 450000 | D36: Dragon 500 | F36: Amace 3D | G36: Proposal / Quote Sent | H36: 20 | M36: shirish shrish | N36: 90000 | O36: INR | P36: 1 | U36: Direct
A37: Q3 | B37: Geo Tijo | C37: 350000 | D37: SF x 10 - TechLabs | F37: Techlab | G37: Sales Qualified Lead | H37: 5 | J37: Have to call on Monday Price negotiation stage looking for the pricing within 40k including gst. | K37: Event | M37: Shekar S | N37: 17500 | O37: INR | P37: 1 | T37: Efy Event | U37: Direct
A38: Q3 | B38: Geo Tijo | C38: 800000 | D38: IIT Thirupathi TD 600 | E38: Twin Dragon 600 | F38: IIT Trichy | G38: Negotiation / Tendering | H38: 50 | J38: Follow Up with OMO with update | K38: Channel Partner | M38: Venkat Global | N38: 400000 | O38: INR | P38: 1 | R38: 50 | S38: 50 | U38: Channel Partner | V38: 3D Printer Hardware
A39: Q3 | B39: Geo Tijo | C39: 300000 | D39: Dragon 400 | F39: NIT Roukela | G39: Proposal / Quote Sent | H39: 20 | J39: Meeting with department head to be scheduled | M39: TANMOY Adikary | N39: 60000 | O39: INR | P39: 1 | U39: Direct | V39: 3D Printer Hardware
A40: Q3 | B40: Geo Tijo | D40: NIPER | F40: NIPER | G40: Discovery Meeting Done | H40: 10 | K40: Website | M40: Dr Sundeep Chaurasia | O40: INR | P40: 1 | Q40: 7 | U40: Direct | V40: 3D Printer Hardware
...

Sheet Sheet1
A2: A | B2: Cash Position | C2: 50 | E2: =C2/C3 -> 3.7537538
A3: B | B3: FC | C3: 13.32 | D3: Min | I3: 15 | J3: 7.5 | K3: =C3-J3 -> 5.82 | L3: =C2/K3 -> 8.5910653
I4: 2
C5: Months | D5: Run rate with existing | I5: 1
B7: Operating | C7: Sustaining
E8: Break Even | F8: Sales
A9: C | B9: Sales | C9: 27 | D9: =C9*12 -> 324 | E9: 3.5
E11: 10 | F11: =E11/12 -> 0.83333333
E13: Sales | F13: 50 | G13: 1 | H13: 3 | I13: 5.5
E15: Sales | F15: 2

Sheet BalanceSheet Summary
C1: THOTA HOSPITALITY LLP
C2: Balance Sheet
C3: 1-Apr-25 to 31-Jan-25
C4: LIABILITIES | F4: Q1 - Apr-Jun | G4: Q2 - Jul-Sept | H4: Q3 - Oct-Dec
C5: Particulars | D5: Subtotal (Rs.) | E5: Total (Rs.)
C6: Capital Account | E6: =SUM(D7:D9) -> -205920
C7: Reserves & Surplus | D7: -321921
C8: Partners Capital | D8: 116001
C10: Loans (Liability) | E10: =SUM(D11:D13) -> 1551043
C11: Partner's Loan-Akshatha | D11: 1323443
C12: Partner's Loan-Tejas | D12: 217000
C13: TVS Credit Services Ltd | D13: 10600
C15: Current Liabilities | E15: =SUM(D16:D20) -> 430388.33
C16: Duties & Taxes | D16: =700902-558705 -> 142197
C17: Provisions | D17: 0
C18: Sundry Creditors | D18: 23603
C19: Reimbursments Payable | D19: =-17931.67+150 -> -17781.67
C20: Salaries Payable | D20: =302372-20002 -> 282370
C22: Profit & Loss A/c | E22: =SUM(D23) -> 4368347.2
C23: Current Period (As per th Books) | D23: ='P&L Detailed'!N49 -> 4368347.2
C25: Total | E25: =SUM(E6:E23) -> 6143858.5
C26: ASSETS
C27: Fixed Assets | E27: =SUM(D28:D30) -> 1848126 | F27: =SUM(E28:E30) -> 0 | G27: =SUM(F28:F30) -> 0 | H27: =SUM(G28:G30) -> 0
C28: Intangible Assets | D28: 69016
C29: Tangible Assets | D29: 1779110
C31: Current Assets | E31: =SUM(D32:D40) -> 1143118 | F31: =SUM(E32:E40) -> 0 | G31: =SUM(F32:F40) -> 0 | H31: =SUM(G32:G40) -> 0
C32: Closing Stock | D32: 0
C33: Deposits (Asset)
C34: Loans & Advances (Asset) | D34: 100167
C35: Sundry Debtors | D35: =10684183-10459551 -> 224632
C36: Cash-in-Hand | D36: 208394
C37: Bank Accounts | D37: 609925
C38: Deferred Expenses
C39: Deferred Tax Asset
C40: TDS - Receivable
C41: Total | E41: =SUM(E27:E40) -> 2991244 | F41: =SUM(F27:F40) -> 0 | G41: =SUM(G27:G40) -> 0 | H41: =SUM(H27:H40) -> 0
C43: Excess Profit not shown in the books | E43: =E25-E41 -> 3152614.5

Sheet Schedule_BS

Sheet Cashflow
A1: THOTA HOSPITALITY LLP
A2: Cash Flow Summary
A3: Particulars | B3: 46137 | C3: 46167 | D3: 46198 | E3: 46228 | F3: 46259 | G3: 46290 | H3: 46320 | I3: 46351 | J3: 46381 | K3: 46048
A4: Bank/Cash Opening Balance | B4: 667981 | C4: 595098 | D4: 538215.85 | E4: 306606.88 | F4: 558764.41 | G4: 591118.38 | H4: 489274.92 | I4: 640540.49 | J4: 897197.59 | K4: 1266575.8
A5: Inflow of Cash :
A6: Current Liabilities | D6: 1379 | G6: 1364 | J6: 2931 | K6: 271
A7: Sundry Creditors | D7: 1379 | G7: 1364 | J7: 2931 | K7: 271
A8: Current Assets | B8: 802290.15 | C8: 896918.72 | D8: 568771.96 | E8: 920440 | F8: 756983.66 | G8: 694013.34 | H8: 1166815.2 | I8: 1081432.1 | J8: 1301836 | K8: 842116.15
A9: Sundry Debtors | B9: 802290.15 | C9: 896918.72 | D9: 568771.96 | E9: 920440 | F9: 756983.66 | G9: 694013.34 | H9: 1166815.2 | I9: 1081432.1 | J9: 1301836 | K9: 842116.15
A10: Indirect Expenses | F10: 1 | G10: 2 | H10: 1.94 | I10: 11.69
A11: Finance Cost | F11: 1 | G11: 2
A12: Rates and Taxes | H12: 1.94 | I12: 11.69
A13: Total | B13: 802290.15 | C13: 896918.72 | D13: 570150.96 | E13: 920440 | F13: 756984.66 | G13: 695379.34 | H13: 1166817.1 | I13: 1081443.8 | J13: 1304767 | K13: 842387.15
A14: Outflow of Cash :
A15: Loans (Liability) | B15: 20000 | C15: 31468 | D15: 15000 | F15: 40000 | H15: 30000 | I15: 30000 | J15: 40000 | K15: 40000
A16: Unsecured Loans | B16: 20000 | C16: 31468 | D16: 15000 | F16: 40000 | H16: 30000 | I16: 30000 | J16: 40000 | K16: 40000
A17: Current Liabilities | B17: 817980.25 | C17: 886874.07 | D17: 777136.23 | E17: 649780.17 | F17: 637008.47 | G17: 784343.6 | H17: 960914.04 | I17: 766120.67 | J17: 890003.27 | K17: 1150498.4
A18: Duties & Taxes | B18: 35960 | C18: 41757 | D18: 43703 | E18: 37126 | F18: 48846 | G18: 83201 | H18: 72325 | I18: 96893 | J18: 101257 | K18: 111709
A19: Sundry Creditors | B19: 405483.25 | C19: 375315.07 | D19: 299888.23 | E19: 269447.17 | F19: 282235.47 | G19: 368792.83 | H19: 528252.56 | I19: 333831.67 | J19: 387811.32 | K19: 556355.77
A20: Employee Advances | B20: 74000 | C20: 115000 | D20: 75962 | E20: 16000
A21: Reimburements | C21: 17633 | D21: 2168 | E21: 18862 | G21: 24017.77 | H21: 34001.48
A22: Salary Payable | B22: 302537 | C22: 337169 | D22: 355415 | E22: 308345 | F22: 305927 | G22: 308332 | H22: 326335 | I22: 335396 | J22: 400934.95 | K22: 482433.63
A23: Current Assets | B23: 2000 | C23: 19441 | D23: 6000 | E23: 15195 | F23: 44425 | G23: 8094 | H23: 23305 | I23: 26883 | J23: 5002 | K23: 117000
A24: Loans & Advances (Asset) | F24: 42000 | G24: 3282 | K24: 100000
A25: Sundry Debtors | B25: 2000 | C25: 19441 | D25: 6000 | E25: 15195 | F25: 2425 | G25: 4812 | H25: 23305 | I25: 26883 | J25: 5002 | K25: 17000
A26: Purchase Accounts | B26: 2450 | C26: 3840 | E26: 30
A27: Thota Kitchen | B27: 2450 | C27: 3840 | E27: 30
A28: Direct Expenses | E28: 8500
A29: Transportation Expenses | E29: 8500
A30: Indirect Expenses | B30: 32742.9 | C30: 12177.8 | D30: 3623.7 | E30: 3277.3 | F30: 3197.22 | G30: 4785.2 | H30: 1332.52 | I30: 1783 | J30: 383.5 | K30: 1645
A31: Administrative Overheads | B31: 5118 | C31: 2576 | D31: 3606 | E31: 3118 | F31: 118 | H31: 1060.82
A32: Finance Cost | B32: 123.9 | C32: 11.8 | D32: 17.7 | E32: 159.3 | F32: 1283.22 | G32: 344.2 | H32: 253.7 | I32: 354 | J32: 383.5 | K32: 354
A33: HR Expenses | G33: 4435 | I33: 1410 | K33: 1291
A34: Employer PT | B34: 2500
A35: Rates and Taxes | F35: 60 | G35: 6 | H35: 18 | I35: 19
A36: Repairs & Maintenance | B36: 25000 | C36: 9590 | F36: 1735
A37: Round Off | B37: 1 | F37: 1
A38: Total | B38: 875173.15 | C38: 953800.87 | D38: 801759.93 | E38: 668282.47 | F38: 724630.69 | G38: 797222.8 | H38: 1015551.6 | I38: 824786.67 | J38: 935388.77 | K38: 1309143.4
A39: Closing Balance | B39: 595098 | C39: 538215.85 | D39: 306606.88 | E39: 558764.41 | F39: 591118.38 | G39: 489274.92 | H39: 640540.49 | I39: 897197.59 | J39: 1266575.8 | K39: 799819.58
A40: Nett Inflow | B40: -72883 | C40: -56882.15 | D40: -231608.97 | E40: 252157.53 | F40: 32353.97 | G40: -101843.46 | H40: 151265.57 | I40: 256657.1 | J40: 369378.24 | K40: -466756.25

Sheet Fundflow_Post Investment
B4: PARTICULARS | C4: Previous Financial Period | F4: Prior Period | H4: Increase (Decrease) | Q4: Current Financial Period
C5: 29.08.2024 - 31.03.2025 | F5: 01.04.2023 to 31.10.2023 | H5: =+C5 -> 29.08.2024 - 31.03.2025 | Q5: 01.04.2025 - 30.09.2025
B6: BEGINNING CASH ON HAND | D6: -3111188.3 | F6: 0 | H6: =+D6-F6 -> -3111188.3 | R6: 6968502.7
B7: Bank Balance | C7: 108495 | Q7: 1705636
B8: Cash Balance | C8: 22571 | Q8: 12866.66
B9: Bank OverDraft | C9: -3242254 | Q9: 5250000
B11: ADD: CASH RECEIPTS
B12: Investment from MEMG | C12: 28000000 | F12: 0 | H12: =+C12-F12 -> 28000000
B13: Collections from Sales | C13: 11238672 | F13: 0 | H13: =+C13-F13 -> 11238672 | Q13: 6653301
B14: Fixed Deposit | C14: 9500000 | Q14: 2500000
B15: Karnataka Elevate Grant | C15: 855180
B16: Misc. Cash Receipts / Refunds | C16: 1019134 | F16: 0 | H16: =+C16-F16 -> 1019134 | Q16: 904406
B17: TOTAL CASH RECEIPTS | D17: 50612986 | F17: =SUM(F12:F16) -> 0 | H17: =+D17-F17 -> 50612986 | R17: 10057707
B19: LESS: CASH PAYMENTS
B20: COST OF GOODS SOLD:
B21: Direct Product/Service Costs | C21: 7668963 | F21: 0 | H21: =+C21-F21 -> 7668963 | Q21: 3045261.6
B22: Customs & Freight Inward | C22: 734039 | F22: 0 | H22: =+C22-F22 -> 734039 | Q22: 495635.67
B23: Other Costs | C23: 50634 | F23: 0 | H23: =+C23-F23 -> 50634 | Q23: 5483
B24: Sub-Total Cost of Goods Sold | D24: 8453635 | F24: =SUM(F21:F23) -> 0 | H24: =+D24-F24 -> 8453635 | R24: 3546380.3
B26: OPERATING EXPENSES:
B27: Advertising and Marketing | C27: 1841965 | F27: 0 | H27: =+C27-F27 -> 1841965 | Q27: 1069115.4
B28: Office & Admin Expenses | C28: 940863 | F28: 0 | H28: =+C28-F28 -> 940863 | Q28: 496555.98
B29: HR Expenses | C29: 7377654 | F29: 0 | H29: =+C29-F29 -> 7377654 | Q29: 5392191
B30: Feight Outward | C30: 175760 | F30: 0 | H30: =+C30-F30 -> 175760 | Q30: 173432.18
B31: R&D | C31: 156839 | F31: 0 | H31: =+C31-F31 -> 156839 | Q31: 31594.49
B32: Miscellaneous Expense | C32: 94290 | F32: 0 | H32: =+C32-F32 -> 94290 | Q32: 10050
B33: Professional Services - Legal Accounting | C33: 2040562 | F33: 0 | H33: =+C33-F33 -> 2040562 | Q33: 703471
B34: Office Rent | C34: 628615 | F34: 0 | H34: =+C34-F34 -> 628615 | Q34: 503118
B35: Travel | C35: 196769 | F35: 0 | H35: =+C35-F35 -> 196769 | Q35: 317630.14
B36: Sub-Total Operating Expenses | D36: 13453318 | F36: =SUM(F27:F35) -> 0 | H36: =+D36-F36 -> 13453318 | R36: 8697158.2
B38: OTHER PAYMENTS :
B39: Society of Innnovation and Development (SLS) | C39: 4200000 | Q39: 2100000
B40: Interest Expense | C40: 121864 | F40: 0 | H40: =+C40-F40 -> 121864 | Q40: 109341
B41: Income Tax Expense | C41: 0 | F41: 0 | H41: =+C41-F41 -> 0
B42: Statutory Payments | C42: 1352903 | Q42: 1186976
B43: Loan Repayments | C43: 3130109 | F43: 0 | H43: =+C43-F43 -> 3130109 | Q43: 96213
B44: Deposits | C44: 12049500
B45: SID Advances (Refundable) | C45: 2239556
B46: Purchase of Fixed Assets | C46: 750277 | Q46: 406978.55
B47: Employee / Other Advances | C47: 45000 | Q47: 10000
...

Sheet FC
A1: Thota Payroll Cost
A2: SR. No. | B2: Dept | C2: Emp Name | D2: Remarks | E2: CTC
A4: 1 | C4: Krupa | E4: 29000
A5: =A4+1 -> 2 | C5: Sanjay | E5: 20000
A6: =A5+1 -> 3 | C6: Niveditha | E6: 21005
A7: =A6+1 -> 4 | C7: Harish | E7: 18000
A8: =A7+1 -> 5 | C8: Babu | E8: 15500
A9: =A8+1 -> 6 | C9: Rajeshwari | E9: 13000
A10: =A9+1 -> 7 | C10: Rahul Ruben | E10: 19154
A11: =A10+1 -> 8 | C11: Padum | E11: 23000
A12: =A11+1 -> 9 | C12: Sagar | E12: 12000
A13: =A12+1 -> 10 | C13: Nisha | E13: 17000
A14: =A13+1 -> 11 | C14: Nanda | E14: 15000
A15: =A14+1 -> 12 | C15: Raju Johan | E15: 20000
A16: =A15+1 -> 13 | C16: Rahul Digar | E16: 14000
... A20: =A19+1 -> 17 | C20: Anusha | E20: 17000
A21: =A20+1 -> 18
D22: Total | E22: =SUM(E4:E21) -> 289659
B23: PARTNER REMUNERATION
A24: 1 | B24: Designated partner | C24: Akshatha R | F24: akshatha@thotahospitality.com Please fill this
A25: 2 | B25: Designated partner | C25: Asha R | F25: akshatha@thotahospitality.com Please fill this
A26: 3 | B26: Designated partner | C26: Tejas R | F26: akshatha@thotahospitality.com Please fill this
D27: Total | E27: =SUM(E24:E26) -> 0
B28: INTERNS
A29: 1 | B29: Digital marketing/Design | E29: 15000
B31: EXTERNAL CONSULTANTS:
A32: =A22+1 -> 1 | B32: Accounting | C32: Suresh Nagaraj | E32: 24000
D34: Total | E34: =SUM(E32:E33) -> 24000
D37: Totat HR Cost | E37: =E22+E27+E29+E34 -> 328659
D38: RENT
D39: Electricity
D40: Finance cost
D41: Office Expenses
D43: Total Fixed Cost / month | E43: =SUM(E37:E41) -> 328659
D45: Total Fixed Cost / Year | E45: =E43*12 -> 3943908
